Workbook

Sheet 德国候选
A1: 德国 RNA PI 扩展候选库（104 位）
A2: 仅德国现任或有近期官方德国机构证据的独立PI/组长；RNA方向优先临床转化，同时覆盖感染、结构化学、计算单细胞与机制研究。检索日期：2026-07-22。
A4: 排名 | B4: 优先级 | C4: PI姓名 | D4: 城市 | E4: 机构 | F4: 当前职位/机构状态 | G4: 生涯阶段 | H4: 研究类型 | I4: 公开Email | J4: 邮箱可信度 | K4: 邮箱来源年份 | L4: RNA专注领域 | M4: 疾病/临床方向 | N4: 临床相关性 | O4: RNA匹配分 | P4: 临床匹配分 | Q4: 联系可信分 | R4: 证据质量分 | S4: 综合匹配分 | T4: 联系优先分 | U4: 代表性论文 | V4: 期刊 | W4: 发表年份 | X4: JIF | Y4: JIF年份 | Z4: 论文/DOI | AA4: JIF来源 | AB4: Email来源 | AC4: 实验室/官方页面 | AD4: OpenAlex | AE4: ORCID | AF4: 复核提示 | AG4: OpenAlex机构列表
A5: 1 | B5: =IF(T5>=95,"A-优先联系",IF(T5>=85,"B-重点关注","C-补充候选")) -> A-优先联系 | C5: Antoine-Emmanuel Saliba | D5: Würzburg | E5: Helmholtz Institute for RNA-based Infection Research | F5: 已核验（德国机构+官网来源） | G5: 成熟/资深PI | H5: 感染与RNA | I5: emmanuel.saliba@helmholtz-hiri.de | J5: 高（机构官网/官方名册） | K5: 2026 | L5: Single-cell RNA analysis of host-pathogen interactions | M5: infectious disease and immune response | N5: 高 | O5: 5 | P5: 5 | Q5: 2 | R5: 2 | S5: =O5*7+P5*7+Q5*10+R5*5 -> 100 | T5: =MIN(100,S5+IF(G5="青年/新组机会",5,0)) -> 100 | U5: Respiratory syncytial viral load drives ciliated cell dedifferentiation and suppresses antiviral immunity | V5: Science Advances | W5: 2026 | X5: 11.7 | Y5: 2024 | Z5: https://doi.org/10.1126/sciadv.aed4499 | AA5: https://www.science.org/journal/sciadv/about | AB5: https://www.helmholtz-hiri.de/fileadmin/HIRI/Research/RNA_Ecosystem/RNA_Faculty_Booklet_WS_2025_26_low.pdf | AC5: https://www.helmholtz-hiri.de/fileadmin/HIRI/Research/RNA_Ecosystem/RNA_Faculty_Booklet_WS_2025_26_low.pdf | AD5: https://openalex.org/A5083429758 | AE5: https://orcid.org/0000-0001-8539-2784 | AF5: 发送前仍建议复核实验室官网 | AG5: University of Würzburg | Centre National des Sciences et Technologies Nucléaires | Helmholtz Centre for Infection Research | Helmholtz Institute for RNA-based Infection Research
A6: 2 | B6: =IF(T6>=95,"A-优先联系",IF(T6>=85,"B-重点关注","C-补充候选")) -> A-优先联系 | C6: Carmen Aguilar | D6: Würzburg | E6: University of Wurzburg | F6: 已核验（德国机构+官网来源） | G6: 青年/新组机会 | H6: 感染与RNA | I6: carmen.aguilar@uni-wuerzburg.de | J6: 高（机构官网/官方名册） | K6: 2026 | L6: Host miRNA and single-cell RNA-seq in infection | M6: urinary tract and bacterial infection | N6: 高 | O6: 5 | P6: 5 | Q6: 2 | R6: 2 | S6: =O6*7+P6*7+Q6*10+R6*5 -> 100 | T6: =MIN(100,S6+IF(G6="青年/新组机会",5,0)) -> 100 | U6: Reprogramming of microRNA expression via E2F1 downregulation promotes Salmonella infection both in infected and bystander cells | V6: Nature Communications | W6: 2021 | X6: 18.1 | Y6: 2025 | Z6: https://doi.org/10.1038/s41467-021-23593-z | AA6: https://www.nature.com/ncomms/ncomms/journal-impact | AB6: https://www.helmholtz-hiri.de/fileadmin/HIRI/Research/RNA_Ecosystem/RNA_Faculty_Booklet_WS_2025_26_low.pdf | AC6: https://www.helmholtz-hiri.de/fileadmin/HIRI/Research/RNA_Ecosystem/RNA_Faculty_Booklet_WS_2025_26_low.pdf | AD6: https://openalex.org/A5018127362 | AE6: https://orcid.org/0000-0002-8437-9585 | AF6: 发送前仍建议复核实验室官网 | AG6: University of Würzburg
A7: 3 | B7: =IF(T7>=95,"A-优先联系",IF(T7>=85,"B-重点关注","C-补充候选")) -> A-优先联系 | C7: Dimitrios Papadopoulos | D7: Würzburg | E7: University of Wurzburg | F7: 已核验（德国机构+官网来源） | G7: 青年/新组机会 | H7: RNA机制实验 | I7: dimitrios.papadopoulos@uni-wuerzburg.de | J7: 高（机构官网/官方名册） | K7: 2026 | L7: Transcription and RNA-associated cancer dependencies | M7: cancer | N7: 高 | O7: 5 | P7: 5 | Q7: 2 | R7: 2 | S7: =O7*7+P7*7+Q7*10+R7*5 -> 100 | T7: =MIN(100,S7+IF(G7="青年/新组机会",5,0)) -> 100 | U7: The MYCN oncoprotein is an RNA-binding accessory factor of the nuclear exosome targeting complex | V7: Molecular Cell | W7: 2024 | X7: 16 | Y7: 2024 | Z7: https://doi.org/10.1016/j.molcel.2024.04.007 | AA7: https://www.cell.com/molecular-cell/home | AB7: https://www.helmholtz-hiri.de/fileadmin/HIRI/Research/RNA_Ecosystem/RNA_Faculty_Booklet_WS_2025_26_low.pdf | AC7: https://www.helmholtz-hiri.de/fileadmin/HIRI/Research/RNA_Ecosystem/RNA_Faculty_Booklet_WS_2025_26_low.pdf | AD7: https://openalex.org/A5090958693 | AE7: https://orcid.org/0000-0002-3415-7407 | AF7: 发送前仍建议复核实验室官网 | AG7: University of Würzburg | Universitätsklinikum Würzburg | St. George Hospital
A8: 4 | B8: =IF(T8>=95,"A-优先联系",IF(T8>=85,"B-重点关注","C-补充候选")) -> A-优先联系 | C8: Dominic Gruen | D8: Würzburg | E8: University of Wurzburg | F8: 已核验（德国机构+官网来源） | G8: 成熟/资深PI | H8: 计算/单细胞 | I8: dominic.gruen@uni-wuerzburg.de | J8: 高（机构官网/官方名册） | K8: 2026 | L8: Single-cell and spatial transcriptomics | M8: immune differentiation, disease and tissue damage | N8: 高 | O8: 5 | P8: 5 | Q8: 2 | R8: 2 | S8: =O8*7+P8*7+Q8*10+R8*5 -> 100 | T8: =MIN(100,S8+IF(G8="青年/新组机会",5,0)) -> 100 | U8: PS-032-Impact of antigen recognition on memory-like HCV-specific CD8+ T-cells | V8: Journal of Hepatology | W8: 2019 | X8: 26.8 | Y8: 2024 | Z8: https://doi.org/10.1016/s0618-8278(19)30038-6 | AA8: https://www.journal-of-hepatology.eu/ | AB8: https://www.helmholtz-hiri.de/fileadmin/HIRI/Research/RNA_Ecosystem/RNA_Faculty_Booklet_WS_2025_26_low.pdf | AC8: https://www.helmholtz-hiri.de/fileadmin/HIRI/Research/RNA_Ecosystem/RNA_Faculty_Booklet_WS_2025_26_low.pdf | AD8: https://openalex.org/A5029274483 | AF8: 发送前仍建议复核实验室官网；代表作标题未直接出现RNA关键词，研究方向仍属RNA范围 | AG8: Max Planck Institute of Immunobiology and Epigenetics
A9: s | B9: =IF(T9>=95,"A-优先联系",IF(T9>=85,"B-重点关注","C-补充候选")) -> A-优先联系 | C9: Franziska Faber | D9: Würzburg | E9: University of Wurzburg / HIRI | F9: 已核验（德国机构+官网来源） | G9: 成熟/资深PI | H9: 感染与RNA | I9: franziska.faber@uni-wuerzburg.de | J9: 高（机构官网/官方名册） | K9: 2026 | L9: Bacterial RNA regulation and virulence | M9: Clostridioides difficile infection and microbiota | N9: 高 | O9: 5 | P9: 5 | Q9: 2 | R9: 2 | S9: =O9*7+P9*7+Q9*10+R9*5 -> 100 | T9: =MIN(100,S9+IF(G9="青年/新组机会",5,0)) -> 100 | U9: The global RNA-binding protein RbpB is a regulator of polysaccharide utilization in Bacteroides thetaiotaomicron | V9: Nature Communications | W9: 2025 | X9: 18.1 | Y9: 2025 | Z9: https://doi.org/10.1038/s41467-024-55383-8 | AA9: https://www.nature.com/ncomms/ncomms/journal-impact | AB9: https://www.helmholtz-hiri.de/fileadmin/HIRI/Research/RNA_Ecosystem/RNA_Faculty_Booklet_WS_2025_26_low.pdf | AC9: https://www.helmholtz-hiri.de/fileadmin/HIRI/Research/RNA_Ecosystem/RNA_Faculty_Booklet_WS_2025_26_low.pdf | AD9: https://openalex.org/A5072398400 | AE9: https://orcid.org/0000-0002-8700-6522 | AF9: 发送前仍建议复核实验室官网 | AG9: University of Würzburg | Centre National des Sciences et Technologies Nucléaires | Helmholtz Centre for Infection Research | Helmholtz Institute for RNA-based Infection Research | Institute of Medical Microbiology and Hygiene
A10: 6 | B10: =IF(T10>=95,"A-优先联系",IF(T10>=85,"B-重点关注","C-补充候选")) -> A-优先联系 | C10: Jonathan Bohlen | D10: Munich | E10: LMU Gene Center | F10: 已核验（德国机构+官网来源） | G10: 青年/新组机会 | H10: RNA机制实验 | I10: j.bohlen@lmu.de | J10: 高（机构官网/官方名册） | K10: 2026 | L10: mRNA translation and tRNA biology in human immunity | M10: immunodeficiency and autoinflammatory disease | N10: 高 | O10: 5 | P10: 5 | Q10: 2 | R10: 2 | S10: =O10*7+P10*7+Q10*10+R10*5 -> 100 | T10: =MIN(100,S10+IF(G10="青年/新组机会",5,0)) -> 100 | U10: Autoantibodies against type I IFNs in humans with alternative NF-κB pathway deficiency | V10: Nature | W10: 2023 | X10: 48.5 | Y10: 2024 | Z10: https://doi.org/10.1038/s41586-023-06717-x | AA10: https://www.nature.com/nature/journal-impact | AB10: https://www.genzentrum.uni-muenchen.de/research-groups/bohlen/index.html | AC10: https://www.genzentrum.uni-muenchen.de/research-groups/bohlen/index.html | AD10: https://openalex.org/A5074184874 | AE10: https://orcid.org/0000-0003-0458-9484 | AF10: 发送前仍建议复核实验室官网 | AG10: Inserm | Université Paris Cité | LMU Klinikum | German Center for Pediatric and Adolescent Rheumatology | German Centre for Cardiovascular Research | Pediatrics and Genetics | Deutsches Herzzentrum München | Human Genetic of Infectious Diseases | Institut des Maladies Génétiques Imagine | Ludwig-Maximilians-Universität München
A11: 7 | B11: =IF(T11>=95,"A-优先联系",IF(T11>=85,"B-重点关注","C-补充候选")) -> A-优先联系 | C11: Julian Stingele | D11: Munich | E11: LMU Gene Center | F11: 已核验（德国机构+官网来源） | G11: 成熟/资深PI | H11: RNA机制实验 | I11: julian.stingele@lmu.de | J11: 高（机构官网/官方名册） | K11: 2026 | L11: RNA damage and RNA-protein crosslink repair | M11: cancer and ageing | N11: 高 | O11: 5 | P11: 5 | Q11: 2 | R11: 2 | S11: =O11*7+P11*7+Q11*10+R11*5 -> 100 | T11: =MIN(100,S11+IF(G11="青年/新组机会",5,0)) -> 100 | U11: Cellular responses to RNA damage | V11: Cell | W11: 2025 | X11: 42.5 | Y11: 2024 | Z11: https://doi.org/10.1016/j.cell.2025.01.005 | AA11: https://www.cell.com/cell/home | AB11: https://www.genzentrum.uni-muenchen.de/research-groups/stingele/index.html | AC11: https://www.genzentrum.uni-muenchen.de/research-groups/stingele/index.html | AD11: https://openalex.org/A5019471057 | AE11: https://orcid.org/0000-0001-6020-2075 | AF11: 发送前仍建议复核实验室官网 | AG11: Centre National des Sciences et Technologies Nucléaires | Ludwig-Maximilians-Universität München
A12: 8 | B12: =IF(T12>=95,"A-优先联系",IF(T12>=85,"B-重点关注","C-补充候选")) -> A-优先联系 | C12: Kathi Zarnack | D12: Würzburg | E12: University of Wurzburg | F12: 已核验（德国机构+官网来源） | G12: 成熟/资深PI | H12: 计算/单细胞 | I12: kathi.zarnack@uni-wuerzburg.de | J12: 高（机构官网/官方名册） | K12: 2026 | L12: Bioinformatics of RNA regulation, splicing and RNA decay | M12: cancer and human disease | N12: 高 | O12: 5 | P12: 5 | Q12: 2 | R12: 2 | S12: =O12*7+P12*7+Q12*10+R12*5 -> 100 | T12: =MIN(100,S12+IF(G12="青年/新组机会",5,0)) -> 100 | U12: An atlas of RNA-dependent proteins in cell division reveals the riboregulation of mitotic protein-protein interactions | V12: Nature Communications | W12: 2025 | X12: 18.1 | Y12: 2025 | Z12: https://doi.org/10.1038/s41467-025-57671-3 | AA12: https://www.nature.com/ncomms/ncomms/journal-impact | AB12: https://www.helmholtz-hiri.de/fileadmin/HIRI/Research/RNA_Ecosystem/RNA_Faculty_Booklet_WS_2025_26_low.pdf | AC12: https://www.helmholtz-hiri.de/fileadmin/HIRI/Research/RNA_Ecosystem/RNA_Faculty_Booklet_WS_2025_26_low.pdf | AD12: https://openalex.org/A5035728142 | AE12: https://orcid.org/0000-0003-3527-3378 | AF12: 发送前仍建议复核实验室官网 | AG12: University of Würzburg | Institute of Molecular Biology
A13: 9 | B13: =IF(T13>=95,"A-优先联系",IF(T13>=85,"B-重点关注","C-补充候选")) -> A-优先联系 | C13: Lorenz Meinel | D13: Würzburg | E13: University of Wurzburg | F13: 已核验（德国机构+官网来源） | G13: 成熟/资深PI | H13: 临床转化/治疗 | I13: lorenz.meinel@uni-wuerzburg.de | J13: 高（机构官网/官方名册） | K13: 2026 | L13: RNA delivery, biomaterials and pharmaceutics | M13: RNA therapeutics and drug delivery | N13: 高 | O13: 5 | P13: 5 | Q13: 2 | R13: 2 | S13: =O13*7+P13*7+Q13*10+R13*5 -> 100 | T13: =MIN(100,S13+IF(G13="青年/新组机会",5,0)) -> 100 | U13: Diagnosing peri-implant disease using the tongue as a 24/7 detector | V13: Nature Communications | W13: 2017 | X13: 18.1 | Y13: 2025 | Z13: https://doi.org/10.1038/s41467-017-00340-x | AA13: https://www.nature.com/ncomms/ncomms/journal-impact | AB13: https://www.helmholtz-hiri.de/fileadmin/HIRI/Research/RNA_Ecosystem/RNA_Faculty_Booklet_WS_2025_26_low.pdf | AC13: https://www.helmholtz-hiri.de/fileadmin/HIRI/Research/RNA_Ecosystem/RNA_Faculty_Booklet_WS_2025_26_low.pdf | AD13: https://openalex.org/A5001051737 | AE13: https://orcid.org/0000-0002-7549-7627 | AF13: 发送前仍建议复核实验室官网；代表作标题未直接出现RNA关键词，研究方向仍属RNA范围 | AG13: University of Würzburg | Helmholtz Institute for RNA-based Infection Research
A14: 10 | B14: =IF(T14>=95,"A-优先联系",IF(T14>=85,"B-重点关注","C-补充候选")) -> A-优先联系 | C14: Manja Marz | D14: Jena | E14: Friedrich Schiller University Jena | F14: 已核验（德国机构+官网来源） | G14: 成熟/资深PI | H14: 感染与RNA | I14: manja@uni-jena.de | J14: 高（机构官网/官方名册） | K14: 2026 | L14: RNA bioinformatics and virus transcriptomics | M14: viral infection and diagnostics | N14: 高 | O14: 5 | P14: 5 | Q14: 2 | R14: 2 | S14: =O14*7+P14*7+Q14*10+R14*5 -> 100 | T14: =MIN(100,S14+IF(G14="青年/新组机会",5,0)) -> 100 | U14: VirJenDB: a FAIR (meta)data and bioinformatics platform for all viruses | V14: Nucleic Acids Research | W14: 2025 | X14: 15 | Y14: 2025 | Z14: https://doi.org/10.1093/nar/gkaf1224 | AA14: https://academic.oup.com/nar/pages/about | AB14: https://www.rna.uni-jena.de/team/ | AC14: https://www.rna.uni-jena.de/team/ | AD14: https://openalex.org/A5041475009 | AE14: https://orcid.org/0000-0003-4783-8823 | AF14: 发送前仍建议复核实验室官网 | AG14: Jena Bioscience (Germany) | Leibniz Institute on Aging - Fritz Lipmann Institute (FLI) | Bioinformatics Institute | Friedrich Schiller University Jena
A15: 11 | B15: =IF(T15>=95,"A-优先联系",IF(T15>=85,"B-重点关注","C-补充候选")) -> A-优先联系 | C15: Marina Chekulaeva | D15: Berlin | E15: Max Delbruck Center | F15: 已核验（德国机构+官网来源） | G15: 成熟/资深PI | H15: RNA机制实验 | I15: marina.chekulaeva@mdc-berlin.de | J15: 高（机构官网/官方名册） | K15: 2026 | L15: Local RNA metabolism, translation and neuronal RNA | M15: ALS and neurodegeneration | N15: 高 | O15: 5 | P15: 5 | Q15: 2 | R15: 2 | S15: =O15*7+P15*7+Q15*10+R15*5 -> 100 | T15: =MIN(100,S15+IF(G15="青年/新组机会",5,0)) -> 100 | U15: Mechanistic insights into the basis of widespread RNA localization | V15: Nature Cell Biology | W15: 2024 | X15: 17.3 | Y15: 2024 | Z15: https://doi.org/10.1038/s41556-024-01444-5 | AA15: https://www.nature.com/ncb/journal-impact | AB15: https://www.mdc-berlin.de/de/chekulaeva | AC15: https://www.mdc-berlin.de/de/chekulaeva | AD15: https://openalex.org/A5070903529 | AE15: https://orcid.org/0000-0002-6868-7887 | AF15: 发送前仍建议复核实验室官网 | AG15: Max Delbrück Center
A16: 12 | B16: =IF(T16>=95,"A-优先联系",IF(T16>=85,"B-重点关注","C-补充候选")) -> A-优先联系 | C16: Roland Beckmann | D16: Munich | E16: LMU Gene Center | F16: 已核验（德国机构+官网来源） | G16: 成熟/资深PI | H16: 结构/化学生物学 | I16: r.beckmann@lmu.de | J16: 高（机构官网/官方名册） | K16: 2026 | L16: Ribosome structure, mRNA surveillance and translation quality control | M16: ribosomopathies and translation disorders | N16: 高 | O16: 5 | P16: 5 | Q16: 2 | R16: 2 | S16: =O16*7+P16*7+Q16*10+R16*5 -> 100 | T16: =MIN(100,S16+IF(G16="青年/新组机会",5,0)) -> 100 | U16: Sni445 recruits box C/D snoRNPs snR4 and snR45 to guide ribosomal RNA acetylation by Kre33 | V16: Nucleic Acids Research | W16: 2026 | X16: 15 | Y16: 2025 | Z16: https://doi.org/10.1093/nar/gkag030 | AA16: https://academic.oup.com/nar/pages/about | AB16: https://www.genzentrum.uni-muenchen.de/research-groups/beckmann/index.html | AC16: https://www.genzentrum.uni-muenchen.de/research-groups/beckmann/index.html | AD16: https://openalex.org/A5010441616 | AE16: https://orcid.org/0000-0003-4291-3898 | AF16: 发送前仍建议复核实验室官网 | AG16: Gene Therapy Laboratory | Ludwig-Maximilians-Universität München
A17: 13 | B17: =IF(T17>=95,"A-优先联系",IF(T17>=85,"B-重点关注","C-补充候选")) -> A-优先联系 | C17: Simone Backes | D17: Würzburg | E17: University of Wurzburg | F17: 已核验（德国机构+官网来源） | G17: 青年/新组机会 | H17: 感染与RNA | I17: simone.backes@uni-wuerzburg.de | J17: 高（机构官网/官方名册） | K17: 2026 | L17: RNA mechanisms in viral replication and host defense | M17: viral infection | N17: 高 | O17: 5 | P17: 5 | Q17: 2 | R17: 2 | S17: =O17*7+P17*7+Q17*10+R17*5 -> 100 | T17: =MIN(100,S17+IF(G17="青年/新组机会",5,0)) -> 100 | U17: Visualizing the transcription and replication of influenza A viral RNAs in cells by multiple direct RNA padlock probing and <i>in situ</i> sequencing (mudRapp-seq) | V17: Nucleic Acids Research | W17: 2025 | X17: 15 | Y17: 2025 | Z17: https://doi.org/10.1093/nar/gkaf461 | AA17: https://academic.oup.com/nar/pages/about | AB17: https://www.helmholtz-hiri.de/fileadmin/HIRI/Research/RNA_Ecosystem/RNA_Faculty_Booklet_WS_2025_26_low.pdf | AC17: https://www.helmholtz-hiri.de/fileadmin/HIRI/Research/RNA_Ecosystem/RNA_Faculty_Booklet_WS_2025_26_low.pdf | AD17: https://openalex.org/A5005739353 | AF17: 发送前仍建议复核实验室官网 | AG17: University of Würzburg
A18: 14 | B18: =IF(T18>=95,"A-优先联系",IF(T18>=85,"B-重点关注","C-补充候选")) -> A-优先联系 | C18: Utz Fischer | D18: Würzburg | E18: University of Wurzburg | F18: 已核验（德国机构+官网来源） | G18: 成熟/资深PI | H18: RNA机制实验 | I18: utz.fischer@biozentrum.uni-wuerzburg.de | J18: 高（机构官网/官方名册） | K18: 2026 | L18: RNA-protein complexes, splicing and RNP assembly | M18: neuromuscular disease and viral infection | N18: 高 | O18: 5 | P18: 5 | Q18: 2 | R18: 2 | S18: =O18*7+P18*7+Q18*10+R18*5 -> 100 | T18: =MIN(100,S18+IF(G18="青年/新组机会",5,0)) -> 100 | U18: Cooperative clamp-mediated promoter recognition by poxviral RNA polymerase and its TBP/TFIIB-like partner | V18: Nature Communications | W18: 2026 | X18: 18.1 | Y18: 2025 | Z18: https://doi.org/10.1038/s41467-026-69571-1 | AA18: https://www.nature.com/ncomms/ncomms/journal-impact | AB18: https://www.helmholtz-hiri.de/fileadmin/HIRI/Research/RNA_Ecosystem/RNA_Faculty_Booklet_WS_2025_26_low.pdf | AC18: https://www.helmholtz-hiri.de/fileadmin/HIRI/Research/RNA_Ecosystem/RNA_Faculty_Booklet_WS_2025_26_low.pdf | AD18: https://openalex.org/A5012562828 | AE18: https://orcid.org/0000-0002-1465-6591 | AF18: 发送前仍建议复核实验室官网 | AG18: University of Würzburg | Helmholtz Institute for RNA-based Infection Research
A19: 15 | B19: =IF(T19>=95,"A-优先联系",IF(T19>=85,"B-重点关注","C-补充候选")) -> A-优先联系 | C19: Matthew Kraushar | D19: Berlin | E19: Charite University Medicine Berlin | F19: 已核验（德国机构+官网来源） | G19: 青年/新组机会 | H19: RNA机制实验 | I19: matthew.kraushar@molgen.mpg.de | J19: 中（近期论文通讯邮箱） | K19: 2025 | L19: Local translation and RNA regulation in neurons | M19: neurodevelopment and neurological disease | N19: 高 | O19: 5 | P19: 5 | Q19: 1 | R19: 2 | S19: =O19*7+P19*7+Q19*10+R19*5 -> 90 | T19: =MIN(100,S19+IF(G19="青年/新组机会",5,0)) -> 95 | U19: Author Correction: A critical period of translational control during brain development at codon resolution | V19: Nature Structural & Molecular Biology | W19: 2025 | X19: 12.1 | Y19: 2024 | Z19: https://doi.org/10.1038/s41594-025-01675-6 | AA19: https://www.nature.com/nsmb/journal-impact | AB19: https://europepmc.org/articles/PMC12440796 | AC19: https://www.rnasociety.org/salons/current-rna-salons/ | AD19: https://openalex.org/A5014690413 | AE19: https://orcid.org/0000-0002-7359-0318 | AF19: 发送前需在机构官网复核 | AG19: Max Planck Institute for Molecular Genetics
A20: 16 | B20: =IF(T20>=95,"A-优先联系",IF(T20>=85,"B-重点关注","C-补充候选")) -> A-优先联系 | C20: Petra Beli | D20: Mainz | E20: Institute of Molecular Biology Mainz | F20: 已核验（德国机构+官网来源） | G20: 青年/新组机会 | H20: RNA机制实验 | I20: p.beli@imb-mainz.de | J20: 中（近期论文通讯邮箱） | K20: 2022 | L20: RNA damage responses and RNA-protein crosslinks | M20: cancer and ageing | N20: 高 | O20: 5 | P20: 5 | Q20: 1 | R20: 2 | S20: =O20*7+P20*7+Q20*10+R20*5 -> 90 | T20: =MIN(100,S20+IF(G20="青年/新组机会",5,0)) -> 95 | U20: The USP11/TCEAL1 complex promotes transcription elongation to sustain oncogenic gene expression in neuroblastoma | V20: Genes & Development | W20: 2025 | X20: 8 | Y20: 2024 | Z20: https://doi.org/10.1101/gad.352166.124 | AA20: https://genesdev.cshlp.org/site/misc/about.xhtml | AB20: https://europepmc.org/articles/PMC9723622 | AC20: https://imb.de/students-postdocs/international-phd-programme/apply-to-ipp/projects-offered | AD20: https://openalex.org/A5012146784 | AE20: https://orcid.org/0000-0001-9507-9820 | AF20: 发送前需在机构官网复核 | AG20: Johannes Gutenberg University Mainz | Institute of Molecular Biology
A21: 17 | B21: =IF(T21>=95,"A-优先联系",IF(T21>=85,"B-重点关注","C-补充候选")) -> A-优先联系 | C21: Katharina Papsdorf | D21: Mainz | E21: Institute of Molecular Biology Mainz | F21: 官网支持，数据库机构滞后—需复核 | G21: 青年/新组机会 | H21: RNA机制实验 | I21: katharina.papsdorf@tum.de | J21: 中低（较早论文通讯邮箱） | K21: 2015 | L21: RNA regulation and molecular mechanisms of ageing | M21: ageing and stress resilience | N21: 高 | O21: 5 | P21: 5 | Q21: 1 | R21: 2 | S21: =O21*7+P21*7+Q21*10+R21*5 -> 90 | T21: =MIN(100,S21+IF(G21="青年/新组机会",5,0)) -> 95 | U21: The CRTC-1 transcriptional domain is required for COMPASS complex-mediated longevity in C. elegans | V21: Nature Aging | W21: 2023 | X21: 17 | Y21: 2024 | Z21: https://doi.org/10.1038/s43587-023-00517-8 | AA21: https://www.nature.com/nataging/journal-impact | AB21: https://europepmc.org/articles/PMC4558792 | AC21: https://www.imb.de/ | AD21: https://openalex.org/A5073229910 | AE21: https://orcid.org/0000-0001-9873-7585 | AF21: 邮箱来源较早，必须复核；OpenAlex当前机构国家未直接匹配 | AG21: Stanford University
A22: 18 | B22: =IF(T22>=95,"A-优先联系",IF(T22>=85,"B-重点关注","C-补充候选")) -> B-重点关注 | C22: Irene Beusch | D22: Würzburg | E22: University of Wurzburg | F22: 官网支持，数据库机构滞后—需复核 | G22: 青年/新组机会 | H22: RNA机制实验 | I22: Irene.beusch@uni-wuerzburg.de | J22: 高（机构官网/官方名册） | K22: 2026 | L22: Mechanisms and regulation of RNA splicing | M22: splicing dysregulation in human disease | N22: 中 | O22: 5 | P22: 3 | Q22: 2 | R22: 2 | S22: =O22*7+P22*7+Q22*10+R22*5 -> 86 | T22: =MIN(100,S22+IF(G22="青年/新组机会",5,0)) -> 91 | U22: A highly sensitive protein-RNA cross-linking mass spectrometry workflow with enhanced structural modeling potential | V22: Nucleic Acids Research | W22: 2025 | X22: 15 | Y22: 2025 | Z22: https://doi.org/10.1093/nar/gkaf523 | AA22: https://academic.oup.com/nar/pages/about | AB22: https://www.helmholtz-hiri.de/fileadmin/HIRI/Research/RNA_Ecosystem/RNA_Faculty_Booklet_WS_2025_26_low.pdf | AC22: https://www.helmholtz-hiri.de/fileadmin/HIRI/Research/RNA_Ecosystem/RNA_Faculty_Booklet_WS_2025_26_low.pdf | AD22: https://openalex.org/A5035063516 | AE22: https://orcid.org/0000-0001-7758-4348 | AF22: 发送前仍建议复核实验室官网；OpenAlex当前机构国家未直接匹配 | AG22: ETH Zurich
A23: 19 | B23: =IF(T23>=95,"A-优先联系",IF(T23>=85,"B-重点关注","C-补充候选")) -> B-重点关注 | C23: Andre Fischer | D23: Göttingen | E23: German Center for Neurodegenerative Diseases / Goettingen | F23: 已核验（德国机构+官网来源） | G23: 成熟/资深PI | H23: RNA机制实验 | I23: andre.fischer@dzne.de | J23: 中（近期论文通讯邮箱） | K23: 2026 | L23: Non-coding RNA, epigenetics and neurodegeneration | M23: Alzheimer's disease and cognitive decline | N23: 高 | O23: 5 | P23: 5 | Q23: 1 | R23: 2 | S23: =O23*7+P23*7+Q23*10+R23*5 -> 90 | T23: =MIN(100,S23+IF(G23="青年/新组机会",5,0)) -> 90 | U23: The lincRNA <i>Pantr1</i> is a FOXG1 target gene conferring site-specific chromatin binding of FOXG1 | V23: Nucleic Acids Research | W23: 2025 | X23: 15 | Y23: 2025 | Z23: https://doi.org/10.1093/nar/gkaf539 | AA23: https://academic.oup.com/nar/pages/about | AB23: https://europepmc.org/articles/PMC13205658 | AC23: https://www.dzne.de | AD23: https://openalex.org/A5040773420 | AE23: https://orcid.org/0000-0001-8546-1161 | AF23: 发送前需在机构官网复核 | AG23: Institute of Molecular Biotechnology | Rolls-Royce (Germany) | Research Institute of Molecular Pathology | Firmenich (Switzerland) | German Primate Center | German Center for Neurodegenerative Diseases | Universitätsmedizin Göttingen | Nanoscale Microscopy and Molecular Physiology of the Brain Cluster of Excellence 171 — DFG Research Center 103 | Vienna Biocenter | University of Göttingen | Medical University of Vienna
A24: 20 | B24: =IF(T24>=95,"A-优先联系",IF(T24>=85,"B-重点关注","C-补充候选")) -> B-重点关注 | C24: Andrea Rentmeister | D24: Münster | E24: University of Muenster | F24: 已核验（德国机构+官网来源） | G24: 成熟/资深PI | H24: 结构/化学生物学 | I24: a.rentmeister@lmu.de | J24: 中（近期论文通讯邮箱） | K24: 2025 | L24: RNA chemical biology, labeling and mRNA engineering | M24: RNA therapeutics and diagnostics | N24: 高 | O24: 5 | P24: 5 | Q24: 1 | R24: 2 | S24: =O24*7+P24*7+Q24*10+R24*5 -> 90 | T24: =MIN(100,S24+IF(G24="青年/新组机会",5,0)) -> 90 | U24: MePMe-seq: antibody-free simultaneous m6A and m5C mapping in mRNA by metabolic propargyl labeling and sequencing | V24: Nature Communications | W24: 2023 | X24: 18.1 | Y24: 2025 | Z24: https://doi.org/10.1038/s41467-023-42832-z | AA24: https://www.nature.com/ncomms/ncomms/journal-impact | AB24: https://europepmc.org/articles/PMC12230757 | AC24: https://www.uni-muenster.de | AD24: https://openalex.org/A5063961340 | AE24: https://orcid.org/0000-0002-3107-4147 | AF24: 发送前需在机构官网复核 | AG24: Ludwig-Maximilians-Universität München
A25: 21 | B25: =IF(T25>=95,"A-优先联系",IF(T25>=85,"B-重点关注","C-补充候选")) -> B-重点关注 | C25: Andreas Beyer | D25: Cologne | E25: University of Cologne | F25: 已核验（德国机构+官网来源） | G25: 成熟/资深PI | H25: 计算/单细胞 | I25: abeyer@mcw.edu | J25: 中（近期论文通讯邮箱） | K25: 2026 | L25: Systems transcriptomics and gene regulation | M25: cancer and complex disease | N25: 高 | O25: 5 | P25: 5 | Q25: 1 | R25: 2 | S25: =O25*7+P25*7+Q25*10+R25*5 -> 90 | T25: =MIN(100,S25+IF(G25="青年/新组机会",5,0)) -> 90 | U25: Lymphoid gene expression supports neuroprotective microglia function | V25: Nature | W25: 2025 | X25: 48.5 | Y25: 2024 | Z25: https://doi.org/10.1038/s41586-025-09662-z | AA25: https://www.nature.com/nature/journal-impact | AB25: https://europepmc.org/articles/PMC12986413 | AC25: https://www.uni-koeln.de | AD25: https://openalex.org/A5022041947 | AE25: https://orcid.org/0000-0002-3891-2123 | AF25: 发送前需在机构官网复核 | AG25: University of Cologne | Medical College of Wisconsin | Cologne Excellence Cluster on Cellular Stress Responses in Aging Associated Diseases | University Hospital Cologne
A26: 22 | B26: =IF(T26>=95,"A-优先联系",IF(T26>=85,"B-重点关注","C-补充候选")) -> B-重点关注 | C26: Andreas Keller | D26: Saarbrücken | E26: Saarland University | F26: 已核验（OpenAlex德国机构） | G26: 成熟/资深PI | H26: 临床转化/治疗 | I26: andreas.keller@ccb.uni-saarland.de | J26: 中（近期论文通讯邮箱） | K26: 2026 | L26: miRNA biomarkers and clinical bioinformatics | M26: liquid biopsy and precision diagnostics | N26: 高 | O26: 5 | P26: 5 | Q26: 1 | R26: 2 | S26: =O26*7+P26*7+Q26*10+R26*5 -> 90 | T26: =MIN(100,S26+IF(G26="青年/新组机会",5,0)) -> 90 | U26: A single-cell atlas to map sex-specific gene-expression changes in blood upon neurodegeneration | V26: Nature Communications | W26: 2025 | X26: 18.1 | Y26: 2025 | Z26: https://doi.org/10.1038/s41467-025-56833-7 | AA26: https://www.nature.com/ncomms/ncomms/journal-impact | AB26: https://europepmc.org/articles/PMC12939772 | AD26: https://openalex.org/A5020280119 | AE26: https://orcid.org/0000-0002-5361-0895 | AF26: 发送前需在机构官网复核 | AG26: Helmholtz Institute for Pharmaceutical Research Saarland | Saarland University
A27: 23 | B27: =IF(T27>=95,"A-优先联系",IF(T27>=85,"B-重点关注","C-补充候选")) -> B-重点关注 | C27: Andreas Pichlmair | D27: Munich | E27: Technical University of Munich | F27: 已核验（德国机构+官网来源） | G27: 成熟/资深PI | H27: 感染与RNA | I27: andreas.pichlmair@tum.de | J27: 中（近期论文通讯邮箱） | K27: 2026 | L27: Viral RNA sensing and antiviral proteomics | M27: viral infection | N27: 高 | O27: 5 | P27: 5 | Q27: 1 | R27: 2 | S27: =O27*7+P27*7+Q27*10+R27*5 -> 90 | T27: =MIN(100,S27+IF(G27="青年/新组机会",5,0)) -> 90 | U27: HCR-Proxy resolves site-specific proximal RNA microenvironments at subcompartmental resolution | V27: Nucleic Acids Research | W27: 2026 | X27: 15 | Y27: 2025 | Z27: https://doi.org/10.1093/nar/gkag086 | AA27: https://academic.oup.com/nar/pages/about | AB27: https://europepmc.org/articles/PMC13156316 | AC27: https://www.virologie.med.tum.de | AD27: https://openalex.org/A5065431449 | AE27: https://orcid.org/0000-0002-0166-1367 | AF27: 发送前需在机构官网复核 | AG27: Helmholtz Zentrum München | Department of Virology | German Center for Infection Research | Institute of Virology of the Slovak Academy of Sciences | Technical University of Munich
A28: 24 | B28: =IF(T28>=95,"A-优先联系",IF(T28>=85,"B-重点关注","C-补充候选")) -> B-重点关注 | C28: Andreas Schlitzer | D28: Bonn | E28: University Hospital Bonn | F28: 已核验（德国机构+官网来源） | G28: 成熟/资深PI | H28: 计算/单细胞 | I28: andreas.schlitzer@uni-bonn.de | J28: 中（近期论文通讯邮箱） | K28: 2023 | L28: Single-cell RNA profiling of human immunity | M28: immune disease and infection | N28: 高 | O28: 5 | P28: 5 | Q28: 1 | R28: 2 | S28: =O28*7+P28*7+Q28*10+R28*5 -> 90 | T28: =MIN(100,S28+IF(G28="青年/新组机会",5,0)) -> 90 | U28: Alternating high-fat diet enhances atherosclerosis by neutrophil reprogramming | V28: Nature | W28: 2024 | X28: 48.5 | Y28: 2024 | Z28: https://doi.org/10.1038/s41586-024-07693-6 | AA28: https://www.nature.com/nature/journal-impact | AB28: https://europepmc.org/articles/PMC10081871 | AC28: https://www.ukbonn.de | AD28: https://openalex.org/A5088693540 | AE28: https://orcid.org/0000-0001-7662-3712 | AF28: 发送前需在机构官网复核 | AG28: University of Bonn
A29: 25 | B29: =IF(T29>=95,"A-优先联系",IF(T29>=85,"B-重点关注","C-补充候选")) -> B-重点关注 | C29: Beatrix Suess | D29: Darmstadt | E29: Technical University Darmstadt | F29: 已核验（德国机构+官网来源） | G29: 成熟/资深PI | H29: RNA机制实验 | I29: bsuess@bio.tu-darmstadt.de | J29: 中（近期论文通讯邮箱） | K29: 2026 | L29: RNA synthetic biology, riboswitches and RNA devices | M29: diagnostics and cell engineering | N29: 高 | O29: 5 | P29: 5 | Q29: 1 | R29: 2 | S29: =O29*7+P29*7+Q29*10+R29*5 -> 90 | T29: =MIN(100,S29+IF(G29="青年/新组机会",5,0)) -> 90 | U29: The interaction between the RNA aptamer Dap1 and DasR mirrors DNA operator site recognition in GntR repressors | V29: Nucleic Acids Research | W29: 2026 | X29: 15 | Y29: 2025 | Z29: https://doi.org/10.1093/nar/gkag489 | AA29: https://academic.oup.com/nar/pages/about | AB29: https://europepmc.org/articles/PMC13254537 | AC29: https://www.tu-darmstadt.de | AD29: https://openalex.org/A5076651173 | AE29: https://orcid.org/0000-0001-8666-6716 | AF29: 发送前需在机构官网复核 | AG29: Technische Universität Darmstadt
A30: 26 | B30: =IF(T30>=95,"A-优先联系",IF(T30>=85,"B-重点关注","C-补充候选")) -> B-重点关注 | C30: Christoph Dieterich | D30: Heidelberg | E30: Heidelberg University | F30: 已核验（德国机构+官网来源） | G30: 成熟/资深PI | H30: 计算/单细胞 | I30: christoph.dieterich@uni-heidelberg.de | J30: 中（近期论文通讯邮箱） | K30: 2025 | L30: Computational RNA biology and transcriptomics | M30: cardiovascular and genetic disease | N30: 高 | O30: 5 | P30: 5 | Q30: 1 | R30: 2 | S30: =O30*7+P30*7+Q30*10+R30*5 -> 90 | T30: =MIN(100,S30+IF(G30="青年/新组机会",5,0)) -> 90 | U30: The two-step purification method ViREn identifies a single NSUN6-mediated 5-methylcytosine modification promoting dengue virus RNA genome turnover | V30: Nucleic Acids Research | W30: 2026 | X30: 15 | Y30: 2025 | Z30: https://doi.org/10.1093/nar/gkag003 | AA30: https://academic.oup.com/nar/pages/about | AB30: https://europepmc.org/articles/PMC12552086 | AC30: https://www.uni-heidelberg.de | AD30: https://openalex.org/A5083154676 | AE30: https://orcid.org/0000-0001-9468-6311 | AF30: 发送前需在机构官网复核 | AG30: Heidelberg University | University Hospital Heidelberg | German Center for Infection Research | German Centre for Cardiovascular Research | Integrative Medicine Institute | Klaus Tschira Foundation | Heidelberg University
A31: 27 | B31: =IF(T31>=95,"A-优先联系",IF(T31>=85,"B-重点关注","C-补充候选")) -> B-重点关注 | C31: Daniel Wilson | D31: Hamburg | E31: University of Hamburg | F31: 已核验（德国机构+官网来源） | G31: 成熟/资深PI | H31: 感染与RNA | I31: daniel.wilson@uni-hamburg.de | J31: 中（近期论文通讯邮箱） | K31: 2026 | L31: Ribosome structure and translation in infection | M31: antibiotics and infectious disease | N31: 高 | O31: 5 | P31: 5 | Q31: 1 | R31: 2 | S31: =O31*7+P31*7+Q31*10+R31*5 -> 90 | T31: =MIN(100,S31+IF(G31="青年/新组机会",5,0)) -> 90 | U31: A natural depsipeptide antibiotic binds the E-site of the bacterial ribosome | V31: Nature | W31: 2026 | X31: 48.5 | Y31: 2024 | Z31: https://doi.org/10.1038/s41586-026-10589-2 | AA31: https://www.nature.com/nature/journal-impact | AB31: https://europepmc.org/articles/PMC13233979 | AC31: https://www.uni-hamburg.de | AD31: https://openalex.org/A5003327550 | AE31: https://orcid.org/0000-0003-3816-3828 | AF31: 发送前需在机构官网复核 | AG31: Universität Hamburg | Hamburg Institut (Germany)
A32: 28 | B32: =IF(T32>=95,"A-优先联系",IF(T32>=85,"B-重点关注","C-补充候选")) -> B-重点关注 | C32: Dorothee Dormann | D32: Mainz | E32: Johannes Gutenberg University Mainz | F32: 已核验（德国机构+官网来源） | G32: 成熟/资深PI | H32: RNA机制实验 | I32: ddormann@uni-mainz.de | J32: 中（近期论文通讯邮箱） | K32: 2025 | L32: RNA-binding protein dysfunction and phase separation | M32: ALS, FTD and neurodegeneration | N32: 高 | O32: 5 | P32: 5 | Q32: 1 | R32: 2 | S32: =O32*7+P32*7+Q32*10+R32*5 -> 90 | T32: =MIN(100,S32+IF(G32="青年/新组机会",5,0)) -> 90 | U32: Intrinsically disordered RNA-binding motifs cooperate to catalyze RNA folding and drive phase separation | V32: Nucleic Acids Research | W32: 2024 | X32: 15 | Y32: 2025 | Z32: https://doi.org/10.1093/nar/gkae1107 | AA32: https://academic.oup.com/nar/pages/about | AB32: https://europepmc.org/articles/PMC12706024 | AC32: https://www.imb.de/students-postdocs/international-phd-programme/ipp-groups/johannes-gutenberg-university-jgu-mainz | AD32: https://openalex.org/A5068527702 | AE32: https://orcid.org/0000-0002-9260-2775 | AF32: 发送前需在机构官网复核 | AG32: Johannes Gutenberg University Mainz | University Medical Center of the Johannes Gutenberg University Mainz | Institute of Molecular Biology | Institute of Molecular Biology
A33: 29 | B33: =IF(T33>=95,"A-优先联系",IF(T33>=85,"B-重点关注","C-补充候选")) -> B-重点关注 | C33: Eva Bartok | D33: Bonn | E33: University Hospital Bonn | F33: 已核验（德国机构+官网来源） | G33: 成熟/资深PI | H33: RNA机制实验 | I33: ebartok@uni-bonn.de | J33: 中（近期论文通讯邮箱） | K33: 2025 | L33: RNA sensing and innate immunity | M33: autoinflammation and infection | N33: 高 | O33: 5 | P33: 5 | Q33: 1 | R33: 2 | S33: =O33*7+P33*7+Q33*10+R33*5 -> 90 | T33: =MIN(100,S33+IF(G33="青年/新组机会",5,0)) -> 90 | U33: RNA-binding proteins hnRNPM and ELAVL1 promote type-I interferon induction downstream of the nucleic acid sensors cGAS and RIG-I | V33: The EMBO Journal | W33: 2024 | X33: 9.4 | Y33: 2024 | Z33: https://doi.org/10.1038/s44318-024-00331-x | AA33: https://www.embopress.org/journal/14602075 | AB33: https://europepmc.org/articles/PMC12359151 | AC33: https://www.ukbonn.de | AD33: https://openalex.org/A5063294321 | AE33: https://orcid.org/0000-0003-0556-1950 | AF33: 发送前需在机构官网复核 | AG33: University of Bonn | University Hospital Bonn
A34: 30 | B34: =IF(T34>=95,"A-优先联系",IF(T34>=85,"B-重点关注","C-补充候选")) -> B-重点关注 | C34: Florian Heyd | D34: Berlin | E34: Freie Universitat Berlin | F34: 已核验（OpenAlex德国机构） | G34: 成熟/资深PI | H34: RNA机制实验 | I34: florian.heyd@fu-berlin.de | J34: 中（近期论文通讯邮箱） | K34: 2025 | L34: Alternative splicing and immune-cell RNA regulation | M34: immune disease and cancer | N34: 高 | O34: 5 | P34: 5 | Q34: 1 | R34: 2 | S34: =O34*7+P34*7+Q34*10+R34*5 -> 90 | T34: =MIN(100,S34+IF(G34="青年/新组机会",5,0)) -> 90 | U34: A Conserved Kinase-Based Body-Temperature Sensor Globally Controls Alternative Splicing and Gene Expression | V34: Molecular Cell | W34: 2020 | X34: 16 | Y34: 2024 | Z34: https://doi.org/10.1016/j.molcel.2020.01.028 | AA34: https://www.cell.com/molecular-cell/home | AB34: https://europepmc.org/articles/PMC12446472 | AD34: https://openalex.org/A5111318513 | AF34: 发送前需在机构官网复核 | AG34: Freie Universität Berlin
A35: 31 | B35: =IF(T35>=95,"A-优先联系",IF(T35>=85,"B-重点关注","C-补充候选")) -> B-重点关注 | C35: Franz Narberhaus | D35: Bochum | E35: Ruhr University Bochum | F35: 已核验（德国机构+官网来源） | G35: 成熟/资深PI | H35: 感染与RNA | I35: franz.narberhaus@rub.de | J35: 中（近期论文通讯邮箱） | K35: 2026 | L35: RNA thermometers and bacterial RNA regulation | M35: infectious disease | N35: 高 | O35: 5 | P35: 5 | Q35: 1 | R35: 2 | S35: =O35*7+P35*7+Q35*10+R35*5 -> 90 | T35: =MIN(100,S35+IF(G35="青年/新组机会",5,0)) -> 90 | U35: Two redox-responsive LysR-type transcription factors control the oxidative stress response of Agrobacterium tumefaciens | V35: Nucleic Acids Research | W35: 2025 | X35: 15 | Y35: 2025 | Z35: https://doi.org/10.1093/nar/gkaf267 | AA35: https://academic.oup.com/nar/pages/about | AB35: https://europepmc.org/articles/PMC13046262 | AC35: https://www.ruhr-uni-bochum.de | AD35: https://openalex.org/A5079185955 | AE35: https://orcid.org/0000-0002-8552-5310 | AF35: 发送前需在机构官网复核 | AG35: Ruhr University Bochum
A36: 32 | B36: =IF(T36>=95,"A-优先联系",IF(T36>=85,"B-重点关注","C-补充候选")) -> B-重点关注 | C36: Friedemann Weber | D36: Giessen | E36: Justus Liebig University Giessen | F36: 已核验（德国机构+官网来源） | G36: 成熟/资深PI | H36: 感染与RNA | I36: friedemann.weber@vetmed.uni-giessen.de | J36: 中（近期论文通讯邮箱） | K36: 2025 | L36: RNA virus replication and innate immunity | M36: emerging viral infection | N36: 高 | O36: 5 | P36: 5 | Q36: 1 | R36: 2 | S36: =O36*7+P36*7+Q36*10+R36*5 -> 90 | T36: =MIN(100,S36+IF(G36="青年/新组机会",5,0)) -> 90 | U36: Crimean–Congo haemorrhagic fever virus uses LDLR to bind and enter host cells | V36: Nature Microbiology | W36: 2024 | X36: 19.4 | Y36: 2024 | Z36: https://doi.org/10.1038/s41564-024-01672-3 | AA36: https://www.nature.com/nmicrobiol/journal-impact | AB36: https://europepmc.org/articles/PMC12568213 | AC36: https://www.uni-giessen.de | AD36: https://openalex.org/A5088808959 | AE36: https://orcid.org/0000-0001-9737-337X | AF36: 发送前需在机构官网复核 | AG36: Justus-Liebig-Universität Gießen
A37: 33 | B37: =IF(T37>=95,"A-优先联系",IF(T37>=85,"B-重点关注","C-补充候选")) -> B-重点关注 | C37: Georg Stoecklin | D37: Heidelberg | E37: Heidelberg University | F37: 已核验（OpenAlex德国机构） | G37: 成熟/资深PI | H37: RNA机制实验 | I37: georg.stoecklin@medma.uni-heidelberg.de | J37: 中（近期论文通讯邮箱） | K37: 2024 | L37: mRNA decay and post-transcriptional control | M37: inflammation and cancer | N37: 高 | O37: 5 | P37: 5 | Q37: 1 | R37: 2 | S37: =O37*7+P37*7+Q37*10+R37*5 -> 90 | T37: =MIN(100,S37+IF(G37="青年/新组机会",5,0)) -> 90 | U37: The two-step purification method ViREn identifies a single NSUN6-mediated 5-methylcytosine modification promoting dengue virus RNA genome turnover | V37: Nucleic Acids Research | W37: 2026 | X37: 15 | Y37: 2025 | Z37: https://doi.org/10.1093/nar/gkag003 | AA37: https://academic.oup.com/nar/pages/about | AB37: https://europepmc.org/articles/PMC11604940 | AD37: https://openalex.org/A5013622991 | AE37: https://orcid.org/0000-0001-9284-9834 | AF37: 发送前需在机构官网复核 | AG37: University of Mannheim | German Cancer Research Center | Heidelberg University | University Hospital Heidelberg | DKFZ-ZMBH Alliance | University Medical Centre Mannheim
A38: 34 | B38: =IF(T38>=95,"A-优先联系",IF(T38>=85,"B-重点关注","C-补充候选")) -> B-重点关注 | C38: Gil Westmeyer | D38: Munich | E38: Technical University of Munich / Helmholtz Munich | F38: 已核验（德国机构+官网来源） | G38: 成熟/资深PI | H38: RNA机制实验 | I38: gil.westmeyer@tum.de | J38: 中（近期论文通讯邮箱） | K38: 2026 | L38: Synthetic RNA sensors and molecular imaging | M38: diagnostics and cell therapy | N38: 高 | O38: 5 | P38: 5 | Q38: 1 | R38: 2 | S38: =O38*7+P38*7+Q38*10+R38*5 -> 90 | T38: =MIN(100,S38+IF(G38="青年/新组机会",5,0)) -> 90 | U38: Non-destructive transcriptomics via vesicular export | V38: Nature Communications | W38: 2026 | X38: 18.1 | Y38: 2025 | Z38: https://doi.org/10.1038/s41467-026-72072-w | AA38: https://www.nature.com/ncomms/ncomms/journal-impact | AB38: https://europepmc.org/articles/PMC13121718 | AC38: https://www.helmholtz-munich.de | AD38: https://openalex.org/A5039343293 | AE38: https://orcid.org/0000-0001-7224-8919 | AF38: 发送前需在机构官网复核 | AG38: Helmholtz Zentrum München | Technical University of Munich
A39: 35 | B39: =IF(T39>=95,"A-优先联系",IF(T39>=85,"B-重点关注","C-补充候选")) -> B-重点关注 | C39: Gunther Hartmann | D39: Bonn | E39: University Hospital Bonn | F39: 已核验（德国机构+官网来源） | G39: 成熟/资深PI | H39: 临床转化/治疗 | I39: gunther.hartmann@uni-bonn.de | J39: 中（近期论文通讯邮箱） | K39: 2025 | L39: Therapeutic RNA and innate immune sensing | M39: cancer immunotherapy and infection | N39: 高 | O39: 5 | P39: 5 | Q39: 1 | R39: 2 | S39: =O39*7+P39*7+Q39*10+R39*5 -> 90 | T39: =MIN(100,S39+IF(G39="青年/新组机会",5,0)) -> 90 | U39: RNA-binding proteins hnRNPM and ELAVL1 promote type-I interferon induction downstream of the nucleic acid sensors cGAS and RIG-I | V39: The EMBO Journal | W39: 2024 | X39: 9.4 | Y39: 2024 | Z39: https://doi.org/10.1038/s44318-024-00331-x | AA39: https://www.embopress.org/journal/14602075 | AB39: https://europepmc.org/articles/PMC12467475 | AC39: https://www.ukbonn.de | AD39: https://openalex.org/A5070273513 | AE39: https://orcid.org/0000-0003-1021-2018 | AF39: 发送前需在机构官网复核 | AG39: University Hospital Bonn
A40: 36 | B40: =IF(T40>=95,"A-优先联系",IF(T40>=85,"B-重点关注","C-补充候选")) -> B-重点关注 | C40: Hiroki Kato | D40: Bonn | E40: University Hospital Bonn | F40: 已核验（德国机构+官网来源） | G40: 成熟/资深PI | H40: 感染与RNA | I40: hkato@uni-bonn.de | J40: 中（近期论文通讯邮箱） | K40: 2025 | L40: Viral RNA recognition and innate immunity | M40: viral infection | N40: 高 | O40: 5 | P40: 5 | Q40: 1 | R40: 2 | S40: =O40*7+P40*7+Q40*10+R40*5 -> 90 | T40: =MIN(100,S40+IF(G40="青年/新组机会",5,0)) -> 90 | U40: A 20-amino-acid Cardiovirus protein exhibits cytokine-mimicry activity to regulate viral replication | V40: Cell Reports | W40: 2025 | X40: 7.5 | Y40: 2024 | Z40: https://doi.org/10.1016/j.celrep.2025.116740 | AA40: https://www.cell.com/cell-reports/home | AB40: https://europepmc.org/articles/PMC12501977 | AC40: https://www.ukbonn.de | AD40: https://openalex.org/A5062077013 | AE40: https://orcid.org/0000-0003-0838-6772 | AF40: 发送前需在机构官网复核 | AG40: Osaka Gakuin University | University of Bonn | Hokkaido University | University Hospital Bonn | Gifu University Hospital | Gifu University | The University of Osaka
A41: 37 | B41: =IF(T41>=95,"A-优先联系",IF(T41>=85,"B-重点关注","C-补充候选")) -> B-重点关注 | C41: Jan Medenbach | D41: Regensburg | E41: University of Regensburg | F41: 已核验（OpenAlex德国机构） | G41: 成熟/资深PI | H41: RNA机制实验 | I41: Jan.Medenbach@ur.de | J41: 中（近期论文通讯邮箱） | K41: 2023 | L41: Translational control and RNA-binding proteins | M41: cancer and metabolic disease | N41: 高 | O41: 5 | P41: 5 | Q41: 1 | R41: 2 | S41: =O41*7+P41*7+Q41*10+R41*5 -> 90 | T41: =MIN(100,S41+IF(G41="青年/新组机会",5,0)) -> 90 | U41: A rapid protocol for ribosome profiling of low input samples | V41: Nucleic Acids Research | W41: 2023 | X41: 15 | Y41: 2025 | Z41: https://doi.org/10.1093/nar/gkad459 | AA41: https://academic.oup.com/nar/pages/about | AB41: https://europepmc.org/articles/PMC10758357 | AD41: https://openalex.org/A5072419423 | AE41: https://orcid.org/0000-0003-0749-7788 | AF41: 发送前需在机构官网复核 | AG41: University of Regensburg | RWTH Aachen University
...

Sheet 临床优先
A1: 临床转化优先（Top 50）
A2: 优先疾病机制、患者样本、诊断标志物、RNA/寡核苷酸治疗、递送、病毒与免疫转化研究；按联系可用性与整体匹配度排序。
A4: 总排名 | B4: PI姓名 | C4: 城市 | D4: 机构 | E4: 公开Email | F4: 邮箱可信度 | G4: 研究类型 | H4: RNA专注领域 | I4: 疾病/临床方向 | J4: 联系优先分 | K4: 代表性论文 | L4: 复核提示
A5: 1 | B5: Antoine-Emmanuel Saliba | C5: Würzburg | D5: Helmholtz Institute for RNA-based Infection Research | E5: emmanuel.saliba@helmholtz-hiri.de | F5: 高（机构官网/官方名册） | G5: 感染与RNA | H5: Single-cell RNA analysis of host-pathogen interactions | I5: infectious disease and immune response | J5: 100 | K5: Respiratory syncytial viral load drives ciliated cell dedifferentiation and suppresses antiviral immunity | L5: 发送前仍建议复核实验室官网
A6: 2 | B6: Carmen Aguilar | C6: Würzburg | D6: University of Wurzburg | E6: carmen.aguilar@uni-wuerzburg.de | F6: 高（机构官网/官方名册） | G6: 感染与RNA | H6: Host miRNA and single-cell RNA-seq in infection | I6: urinary tract and bacterial infection | J6: 100 | K6: Reprogramming of microRNA expression via E2F1 downregulation promotes Salmonella infection both in infected and bystander cells | L6: 发送前仍建议复核实验室官网
A7: 3 | B7: Dimitrios Papadopoulos | C7: Würzburg | D7: University of Wurzburg | E7: dimitrios.papadopoulos@uni-wuerzburg.de | F7: 高（机构官网/官方名册） | G7: RNA机制实验 | H7: Transcription and RNA-associated cancer dependencies | I7: cancer | J7: 100 | K7: The MYCN oncoprotein is an RNA-binding accessory factor of the nuclear exosome targeting complex | L7: 发送前仍建议复核实验室官网
A8: 4 | B8: Dominic Gruen | C8: Würzburg | D8: University of Wurzburg | E8: dominic.gruen@uni-wuerzburg.de | F8: 高（机构官网/官方名册） | G8: 计算/单细胞 | H8: Single-cell and spatial transcriptomics | I8: immune differentiation, disease and tissue damage | J8: 100 | K8: PS-032-Impact of antigen recognition on memory-like HCV-specific CD8+ T-cells | L8: 发送前仍建议复核实验室官网；代表作标题未直接出现RNA关键词，研究方向仍属RNA范围
A9: 5 | B9: Franziska Faber | C9: Würzburg | D9: University of Wurzburg / HIRI | E9: franziska.faber@uni-wuerzburg.de | F9: 高（机构官网/官方名册） | G9: 感染与RNA | H9: Bacterial RNA regulation and virulence | I9: Clostridioides difficile infection and microbiota | J9: 100 | K9: The global RNA-binding protein RbpB is a regulator of polysaccharide utilization in Bacteroides thetaiotaomicron | L9: 发送前仍建议复核实验室官网
A10: 6 | B10: Jonathan Bohlen | C10: Munich | D10: LMU Gene Center | E10: j.bohlen@lmu.de | F10: 高（机构官网/官方名册） | G10: RNA机制实验 | H10: mRNA translation and tRNA biology in human immunity | I10: immunodeficiency and autoinflammatory disease | J10: 100 | K10: Autoantibodies against type I IFNs in humans with alternative NF-κB pathway deficiency | L10: 发送前仍建议复核实验室官网
A11: 7 | B11: Julian Stingele | C11: Munich | D11: LMU Gene Center | E11: julian.stingele@lmu.de | F11: 高（机构官网/官方名册） | G11: RNA机制实验 | H11: RNA damage and RNA-protein crosslink repair | I11: cancer and ageing | J11: 100 | K11: Cellular responses to RNA damage | L11: 发送前仍建议复核实验室官网
A12: 8 | B12: Kathi Zarnack | C12: Würzburg | D12: University of Wurzburg | E12: kathi.zarnack@uni-wuerzburg.de | F12: 高（机构官网/官方名册） | G12: 计算/单细胞 | H12: Bioinformatics of RNA regulation, splicing and RNA decay | I12: cancer and human disease | J12: 100 | K12: An atlas of RNA-dependent proteins in cell division reveals the riboregulation of mitotic protein-protein interactions | L12: 发送前仍建议复核实验室官网
A13: 9 | B13: Lorenz Meinel | C13: Würzburg | D13: University of Wurzburg | E13: lorenz.meinel@uni-wuerzburg.de | F13: 高（机构官网/官方名册） | G13: 临床转化/治疗 | H13: RNA delivery, biomaterials and pharmaceutics | I13: RNA therapeutics and drug delivery | J13: 100 | K13: Diagnosing peri-implant disease using the tongue as a 24/7 detector | L13: 发送前仍建议复核实验室官网；代表作标题未直接出现RNA关键词，研究方向仍属RNA范围
A14: 10 | B14: Manja Marz | C14: Jena | D14: Friedrich Schiller University Jena | E14: manja@uni-jena.de | F14: 高（机构官网/官方名册） | G14: 感染与RNA | H14: RNA bioinformatics and virus transcriptomics | I14: viral infection and diagnostics | J14: 100 | K14: VirJenDB: a FAIR (meta)data and bioinformatics platform for all viruses | L14: 发送前仍建议复核实验室官网
A15: 11 | B15: Marina Chekulaeva | C15: Berlin | D15: Max Delbruck Center | E15: marina.chekulaeva@mdc-berlin.de | F15: 高（机构官网/官方名册） | G15: RNA机制实验 | H15: Local RNA metabolism, translation and neuronal RNA | I15: ALS and neurodegeneration | J15: 100 | K15: Mechanistic insights into the basis of widespread RNA localization | L15: 发送前仍建议复核实验室官网
A16: 12 | B16: Roland Beckmann | C16: Munich | D16: LMU Gene Center | E16: r.beckmann@lmu.de | F16: 高（机构官网/官方名册） | G16: 结构/化学生物学 | H16: Ribosome structure, mRNA surveillance and translation quality control | I16: ribosomopathies and translation disorders | J16: 100 | K16: Sni445 recruits box C/D snoRNPs snR4 and snR45 to guide ribosomal RNA acetylation by Kre33 | L16: 发送前仍建议复核实验室官网
... A54: 51 | B54: Mirka Uhlirova | C54: Cologne | D54: University of Cologne | E54: mirka.uhlirova@uni-koeln.de | F54: 中（近期论文通讯邮箱） | G54: RNA机制实验 | H54: Non-coding RNA and stress-response gene regulation | I54: cancer and inflammation | J54: 90 | K54: Xrp1 governs the stress response program to spliceosome dysfunction | L54: 发送前需在机构官网复核

Sheet 青年新组
A1: 青年/新组机会（9 位）
A2: 独立时间较短或官方资料明确标为Junior/Emmy Noether/新组长；通常课题参与空间更大，但经费与团队规模需要逐一确认。
A4: 总排名 | B4: PI姓名 | C4: 城市 | D4: 机构 | E4: 公开Email | F4: RNA专注领域 | G4: 疾病方向 | H4: 联系优先分 | I4: 代表性论文 | J4: 官方/来源页面 | K4: 注意事项
A5: 2 | B5: Carmen Aguilar | C5: Würzburg | D5: University of Wurzburg | E5: carmen.aguilar@uni-wuerzburg.de | F5: Host miRNA and single-cell RNA-seq in infection | G5: urinary tract and bacterial infection | H5: 100 | I5: Reprogramming of microRNA expression via E2F1 downregulation promotes Salmonella infection both in infected and bystander cells | J5: https://www.helmholtz-hiri.de/fileadmin/HIRI/Research/RNA_Ecosystem/RNA_Faculty_Booklet_WS_2025_26_low.pdf | K5: 发送前仍建议复核实验室官网
A6: 3 | B6: Dimitrios Papadopoulos | C6: Würzburg | D6: University of Wurzburg | E6: dimitrios.papadopoulos@uni-wuerzburg.de | F6: Transcription and RNA-associated cancer dependencies | G6: cancer | H6: 100 | I6: The MYCN oncoprotein is an RNA-binding accessory factor of the nuclear exosome targeting complex | J6: https://www.helmholtz-hiri.de/fileadmin/HIRI/Research/RNA_Ecosystem/RNA_Faculty_Booklet_WS_2025_26_low.pdf | K6: 发送前仍建议复核实验室官网
A7: 6 | B7: Jonathan Bohlen | C7: Munich | D7: LMU Gene Center | E7: j.bohlen@lmu.de | F7: mRNA translation and tRNA biology in human immunity | G7: immunodeficiency and autoinflammatory disease | H7: 100 | I7: Autoantibodies against type I IFNs in humans with alternative NF-κB pathway deficiency | J7: https://www.genzentrum.uni-muenchen.de/research-groups/bohlen/index.html | K7: 发送前仍建议复核实验室官网
A8: 13 | B8: Simone Backes | C8: Würzburg | D8: University of Wurzburg | E8: simone.backes@uni-wuerzburg.de | F8: RNA mechanisms in viral replication and host defense | G8: viral infection | H8: 100 | I8: Visualizing the transcription and replication of influenza A viral RNAs in cells by multiple direct RNA padlock probing and <i>in situ</i> sequencing (mudRapp-seq) | J8: https://www.helmholtz-hiri.de/fileadmin/HIRI/Research/RNA_Ecosystem/RNA_Faculty_Booklet_WS_2025_26_low.pdf | K8: 发送前仍建议复核实验室官网
A9: 15 | B9: Matthew Kraushar | C9: Berlin | D9: Charite University Medicine Berlin | E9: matthew.kraushar@molgen.mpg.de | F9: Local translation and RNA regulation in neurons | G9: neurodevelopment and neurological disease | H9: 95 | I9: Author Correction: A critical period of translational control during brain development at codon resolution | J9: https://www.rnasociety.org/salons/current-rna-salons/ | K9: 发送前需在机构官网复核
A10: 16 | B10: Petra Beli | C10: Mainz | D10: Institute of Molecular Biology Mainz | E10: p.beli@imb-mainz.de | F10: RNA damage responses and RNA-protein crosslinks | G10: cancer and ageing | H10: 95 | I10: The USP11/TCEAL1 complex promotes transcription elongation to sustain oncogenic gene expression in neuroblastoma | J10: https://imb.de/students-postdocs/international-phd-programme/apply-to-ipp/projects-offered | K10: 发送前需在机构官网复核
A11: 17 | B11: Katharina Papsdorf | C11: Mainz | D11: Institute of Molecular Biology Mainz | E11: katharina.papsdorf@tum.de | F11: RNA regulation and molecular mechanisms of ageing | G11: ageing and stress resilience | H11: 95 | I11: The CRTC-1 transcriptional domain is required for COMPASS complex-mediated longevity in C. elegans | J11: https://www.imb.de/ | K11: 邮箱来源较早，必须复核；OpenAlex当前机构国家未直接匹配
A12: 18 | B12: Irene Beusch | C12: Würzburg | D12: University of Wurzburg | E12: Irene.beusch@uni-wuerzburg.de | F12: Mechanisms and regulation of RNA splicing | G12: splicing dysregulation in human disease | H12: 91 | I12: A highly sensitive protein-RNA cross-linking mass spectrometry workflow with enhanced structural modeling potential | J12: https://www.helmholtz-hiri.de/fileadmin/HIRI/Research/RNA_Ecosystem/RNA_Faculty_Booklet_WS_2025_26_low.pdf | K12: 发送前仍建议复核实验室官网；OpenAlex当前机构国家未直接匹配
A13: 75 | B13: Marie-Luise Winz | C13: Mainz | D13: Johannes Gutenberg University Mainz | E13: mwinz@uni-mainz.de | F13: Co-translational RNA quality control | G13: translation-associated disease mechanisms | H13: 81 | I13: Yeast elongation factor homolog New1 protects a subset of mRNAs from degradation by no-go decay | J13: https://www.imb.de/students-postdocs/international-phd-programme/ipp-groups/johannes-gutenberg-university-jgu-mainz | K13: 发送前需在机构官网复核

Sheet 城市方向统计
A1: 德国候选覆盖与分布
A2: 统计来自最终合格候选；城市集中度可以帮助你结合生活成本、产业生态和合作网络规划申请批次。
A4: 核心指标 | B4: 数量 | D4: 城市 | E4: 候选数 | F4: 占比 | H4: 研究类型 | I4: 候选数
A5: 最终德国候选 | B5: =COUNTA(德国候选!$C$5:$C$108) -> 104 | D5: Würzburg | E5: =COUNTIF(德国候选!$D$5:$D$108,D5) -> 15 | F5: =E5/$B$5 -> 0.14423077 | H5: RNA机制实验 | I5: =COUNTIF(德国候选!$H$5:$H$108,H5) -> 49
A6: 有公开Email | B6: =COUNTIF(德国候选!$I$5:$I$108,"<>未找到") -> 103 | D6: Berlin | E6: =COUNTIF(德国候选!$D$5:$D$108,D6) -> 14 | F6: =E6/$B$5 -> 0.13461538 | H6: 感染与RNA | I6: =COUNTIF(德国候选!$H$5:$H$108,H6) -> 18
A7: 邮箱可信度中等或较高 | B7: =COUNTIF(德国候选!$Q$5:$Q$108,">0") -> 101 | D7: Heidelberg | E7: =COUNTIF(德国候选!$D$5:$D$108,D7) -> 12 | F7: =E7/$B$5 -> 0.11538462 | H7: 计算/单细胞 | I7: =COUNTIF(德国候选!$H$5:$H$108,H7) -> 14
A8: 临床相关性高 | B8: =COUNTIF(德国候选!$N$5:$N$108,"高") -> 74 | D8: Munich | E8: =COUNTIF(德国候选!$D$5:$D$108,D8) -> 10 | F8: =E8/$B$5 -> 0.096153846 | H8: 结构/化学生物学 | I8: =COUNTIF(德国候选!$H$5:$H$108,H8) -> 14
A9: 青年/新组机会 | B9: =COUNTIF(德国候选!$G$5:$G$108,"青年/新组机会") -> 9 | D9: Göttingen | E9: =COUNTIF(德国候选!$D$5:$D$108,D9) -> 10 | F9: =E9/$B$5 -> 0.096153846 | H9: 临床转化/治疗 | I9: =COUNTIF(德国候选!$H$5:$H$108,H9) -> 9
A10: 德国机构/官网证据 | B10: =COUNTIF(德国候选!$R$5:$R$108,"=2") -> 103 | D10: Mainz | E10: =COUNTIF(德国候选!$D$5:$D$108,D10) -> 7 | F10: =E10/$B$5 -> 0.067307692
A11: RNA标题直接匹配 | B11: 98 | D11: Bonn | E11: =COUNTIF(德国候选!$D$5:$D$108,D11) -> 4 | F11: =E11/$B$5 -> 0.038461538
D12: Frankfurt | E12: =COUNTIF(德国候选!$D$5:$D$108,D12) -> 4 | F12: =E12/$B$5 -> 0.038461538
D13: Cologne | E13: =COUNTIF(德国候选!$D$5:$D$108,D13) -> 3 | F13: =E13/$B$5 -> 0.028846154
D14: Giessen | E14: =COUNTIF(德国候选!$D$5:$D$108,D14) -> 3 | F14: =E14/$B$5 -> 0.028846154
D15: Jena | E15: =COUNTIF(德国候选!$D$5:$D$108,D15) -> 2 | F15: =E15/$B$5 -> 0.019230769
D16: Hamburg | E16: =COUNTIF(德国候选!$D$5:$D$108,D16) -> 2 | F16: =E16/$B$5 -> 0.019230769
D17: Regensburg | E17: =COUNTIF(德国候选!$D$5:$D$108,D17) -> 2 | F17: =E17/$B$5 -> 0.019230769
D18: Halle | E18: =COUNTIF(德国候选!$D$5:$D$108,D18) -> 2 | F18: =E18/$B$5 -> 0.019230769
D19: Münster | E19: =COUNTIF(德国候选!$D$5:$D$108,D19) -> 1 | F19: =E19/$B$5 -> 0.0096153846
D20: Saarbrücken | E20: =COUNTIF(德国候选!$D$5:$D$108,D20) -> 1 | F20: =E20/$B$5 -> 0.0096153846
D21: Darmstadt | E21: =COUNTIF(德国候选!$D$5:$D$108,D21) -> 1 | F21: =E21/$B$5 -> 0.0096153846
D22: Bochum | E22: =COUNTIF(德国候选!$D$5:$D$108,D22) -> 1 | F22: =E22/$B$5 -> 0.0096153846
D23: Tübingen | E23: =COUNTIF(德国候选!$D$5:$D$108,D23) -> 1 | F23: =E23/$B$5 -> 0.0096153846
... D32: Kiel | E32: =COUNTIF(德国候选!$D$5:$D$108,D32) -> 1 | F32: =E32/$B$5 -> 0.0096153846

Sheet 说明与方法
A1: 说明、筛选标准与申请建议
A2: 本表追求德国覆盖面，同时用证据和风险提示区分“可直接联系”与“需要进一步人工核验”的候选。
A4: 项目 | B4: 说明
A5: 候选范围 | B5: 从 129 位德国RNA相关独立PI/组长种子池中，保留 104 位有RNA相关代表作且所列期刊近期公开JIF>5的候选。
A6: 学术范围 | B6: RNA生物学、剪接/加工、RNA修饰、非编码RNA、翻译/核糖体、RNA病毒与感染、RNA治疗/诊断、RNA结构化学，以及以RNA为核心的单细胞/空间转录组。
A7: 临床优先 | B7: 标为高的方向通常涉及患者样本、疾病机制、诊断、RNA药物/递送、感染、免疫、癌症、心血管或神经退行疾病。基础机制组仍被纳入，但单独标注研究类型。
A8: 影响力门槛 | B8: 每位候选至少附一篇相关代表作和JIF来源。JIF会逐年变化，因此这里把它作为用户指定的最低筛选门槛，而不是实验室质量的唯一判断。
A9: 评分公式 | B9: 综合匹配分 = RNA匹配分×7 + 临床匹配分×7 + 联系可信分×10 + 证据质量分×5；明确的青年/新组机会在联系优先分中加5分并封顶100。
A10: 邮箱来源 | B10: 高：机构官网或2025–26官方RNA名册；中：近期论文通讯邮箱且与PI姓氏匹配；低：疑似合作者邮箱。无论级别，正式发送前都应在最新实验室官网复核。
A11: 机构状态 | B11: 优先使用OpenAlex最近机构国家与官方实验室/名册交叉验证。个别新近转岗者会出现数据库滞后，表中已明确标为需复核。
A12: 青年新组 | B12: 青年/新组工作表只包含官方资料明确标为Junior Group Leader、Emmy Noether或新近独立的候选；这不是对年龄的判断。
A13: 首轮策略 | B13: 先从临床优先表中按疾病方向选10–15位，再从青年新组表补5位；逐一阅读最近2–3篇论文、检查招聘页和经费，再发送定制邮件。
A14: 检索来源 | B14: OpenAlex、Europe PMC、期刊/出版方页面、机构实验室主页，以及Helmholtz HIRI 2025–26 Würzburg RNA Faculty官方名册。所有行保留可审计URL。
A15: 检索日期 | B15: 2026-07-22（Europe/Berlin）
